Workbook
Name \A: #REF!
Name \A: #REF!
Name \A: #REF!
Name \A: #REF!
Name \A: #REF!
Name \A: #REF!
Name \A: #REF!
Name \A: #REF!
Name \A: #REF!
Name \A: #REF!
Name \A: #REF!
Name \A: #REF!
Name \A: #REF!
Name \G: #REF!
Name \G: #REF!
Name \G: #REF!
Name \G: #REF!
Name \G: #REF!
Name \G: #REF!
Name \G: #REF!
Name \G: #REF!
Name \G: #REF!
Name \G: #REF!
Name \G: #REF!
Name \G: #REF!
Name \X: #REF!
Name \X: #REF!
Name \X: #REF!
Name \X: #REF!
Name \X: #REF!
Name \X: #REF!
Name \X: #REF!
Name \X: #REF!
Name \X: #REF!
Name \X: #REF!
Name \X: #REF!
Name \X: #REF!
Name ___DAT1: #REF!
Name ___DAT1: #REF!
Name ___DAT1: #REF!
Name ___DAT1: #REF!
Name ___DAT1: #REF!
Name ___DAT1: #REF!
Name ___DAT1: #REF!
Name ___DAT1: #REF!
Name ___DAT1: #REF!
Name ___DAT1: #REF!
Name ___DAT1: #REF!
Name ___DAT1: #REF!
Name ___DAT10: #REF!
Name ___DAT10: #REF!
Name ___DAT10: #REF!
Name ___DAT10: #REF!
Name ___DAT10: #REF!
Name ___DAT10: #REF!
Name ___DAT10: #REF!
Name ___DAT10: #REF!
Name ___DAT10: #REF!
Name ___DAT10: #REF!
Name ___DAT10: #REF!

Sheet COVER PAGE
A1: LAGOS STATE INTERNAL REVENUE SERVICES
A4: TAX AUDIT REPORT
A6: NAME OF THE COMPANY:
A7: 3C HUB BRAND MANAGEMENT LIMITED
A10: PERIOD OF AUDIT:
A11: 2023&2024
A14: PREPARED BY
A15: PETABIZ NIGERIA LIMITED

Sheet Status
A4: AUDIT REPORT
A10: STATUS REPORT ON 3C HUB BRAND MANAGEMENT LIMITED
A13: THE COMPANY
A14: 3C HUB BRAND MANAGEMENT LIMITED was incorporated under COMPANIES AND ALLIED MATTERS
A15: ACT 2004 as a Limited Company on the 5TH June 2014 with RC number 1195308
A16: The company is into Trading
A19: STAFF
A20: The Company engaged the services of 217 Local staff and 5 expatriate staff in the 2021 year audit.
A23: PAYE
A24: There were evidence of PAYE deducted from the company's staff emolument and remittances were made.
A25: The evidence of remittances were included in the report of the company.
A28: WITHHOLDING TAX
... A38: There was evidence of payment in this regard.

Sheet CONTENT
A2: Table of Contents | H2: Page
A4: Company Profile | H4: 1
A6: Audit Check List | H6: 2
A8: Staff Cost Analysis | H8: 3
A10: Payroll Cost Analysis | H10: 4
A12: Analysis of Director's Emoluments | H12: 5
A14: Analysis of Payroll Cost - Expatriate | H14: 6
A16: Analysis of Operating Expenses | H16: 7
A18: Schedule of Withholding Tax | H18: 8
A20: Schedule of List of Tax Payers | H20: 9
A22: Summary of Tax Remittances Receipts PAYE | H22: 10
A24: Schedule of Withholding Tax Remittances | H24: 11
A26: Business/Office Location of Tax Payer | H26: 12
A28: Development Levy | H28: 13
A30: Hotel Occupancy & Restaurant Consumption Check List | H30: 14
A32: Hotel Occupancy & Restaurant Consumption | H32: 15

Sheet FIELD REPORT FORM
A1: COMPANY PROFILE
A6: 1 | B6: NAME OF COMPANY: | H6: 3C HUB BRAND MANAGEMENT LIMITED
A9: 2 | B9: YEAR OF INCORPORATION: | H9: 5TH JUNE 2014
A12: 3a | B12: PRESENT ADDRESS AND LOCATION: | H12: 20, OBAFEMI AWOLOWA WAY, IKEJA, LAGOS
A14: 3b | B14: CORPORATE E-MAIL ADDRESS: | H14: finance.3cng@yiwill.com
A17: 4 | B17: NATURE OF BUSINESS: | H17: TRADING
A20: 5a | B20: PHONE NO OF THE MD/THE ACCOUNTANT: | H20: 08142121843
A22: 5b | B22: CONTACT's E-MAIL ADDRESS:
A25: 6 | B25: RC NO: | H25: 1195308'
A28: 7 | B28: AGENCY REF: | H28: LA/IRS/TA/C14326/FS033/NA/38428//05/25
A31: 8 | B31: SECTOR: | H31: TRADING
A34: 9 | B34: YEAR END: | H34: 31ST DECEMBER
A37: 10 | B37: PERIOD OF AUDIT: | J37: 2023&2024
A40: 11 | B40: NAME & SIGN OF TAMA: | H40: PETABIZ NIGERIA LIMITED
H42: JUNAID-OWOKORODU KAFILAT
A43: 12 | B43: NAME & SIGN OF BIR STAFF: | H43: SOYOMBO ANTHONY ADEYEMI
H44: AKINRINOLA ADEKEMI OLUSEUN

Sheet Audit Check List
C4: STATUTORY TAX AUDIT - BASIC INFORMATION CHECKLIST | J4: RC NO : 1195308
C5: COMPANY NAME : 3C HUB BRAND MANAGEMENT | J5: TAX STATION REGISTERED:
C6: ADDRESS : 20, OBAFEMI AWOLOWA WAY, IKEJA, LAGOS
C7: YEARS OF ASSESSMENT : 2023&2024 | J7: AUDIT TEAM LEADER:MRS JUNAID-OWOKORODU KAFILAT
C8: DATE OF AUDIT : 18/07/2025
J9: TAMA: PETABIZ NIGERIA LIMITED
D10: 2023&2024 | E10: 2014 | F10: 2013 | G10: 2012 | H10: 2011 | I10: 2010 | J10: REMARKS
B11: 1 | C11: General Information
C12: Certificate of Incorporation
C13: CAC Form 2 & 7
C14: Audited Financial Statement
C15: Management Account
C16: Trial Balance/General Ledger
C17: Evidence of Business Premises Paid
C18: List of Branches in Nigeria
C19: List of Location/Offices in Lagos
C20: Evidence of Previous Year Audit
B23: 2 | C23: PAYE
C24: Staff Monthly Payroll
C25: Schedule Upront/Quarterly Payments
C26: Schedule Non-payroll payments to Staff
C27: Schedule of Benefits-in-kind to staff
C28: Staff Salary Schedule to Bank
C29: Employer Annual Declaration Form (H1)
C30: Sample of Employment Letters
C31: Scheme of Pension Remittance
C32: Evidence of PAYE Remittance
C33: Evidence of Development Levy Paid
B36: 3 | C36: Directors & Senior Management Staff
C37: Directors Emolument/Senior Management Staff Payroll
C38: Direct/Self Assessment
C39: Contract of Employment/Contract Agreement
C40: Schedule of Benefits-in-kind (Perquisites)
C41: Scheme of Pension Remittance
C42: Evidence of PAYE Remittance
C43: Evidence of Development Levy Paid
C44: Evidence of Life Assurance Policy
C45: Evidence of Gratuities
C46: Evidence of NHIS
C47: Evidence of NHF
...

Sheet Staff Cost Analysis
B2: Analysis of Employee Benefit/Staff Cost
C4: 2023&2024
C5: Naira
B6: Total Staff Cost As Par Audited Financial Statement
B8: Total as par Audited Financial Statement
B9: Number Staff
B10: Employee Salaries & Wages
B11: Pension Contribution
B12: Other employee benefits
B15: Resident in Lagos
B16: Number Staff
B17: Employee Salaries & Wages
B18: Pension Contribution
B19: Other employee benefits

Sheet Payroll Cost Analysis 2023
D2: Analysis of Payroll Cost - Nigerian Staff | H2: 2023
B4: S/N | C4: Employees Details | K4: Payroll Items | V4: Deductions
C5: Staff Number | D5: Last Name | E5: First Name | F5: Other Name | G5: Designation | H5: ABC - ID | I5: Location | J5: No. of Month | K5: Basic | L5: Pensionable Income | O5: Non Pensionable Income | T5: One-Off Allowances | U5: Total Pay | V5: Pensions | W5: NHIS | X5: Gratuity | Y5: NHF | Z5: Life Assurance Premium
L6: Housing | M6: Transport | N6: BHT | O6: Utility | P6: Dressing | Q6: Lunch | R6: Leave | S6: Others
B7: 1 | N7: =K7+L7+M7 -> 0 | V7: =8%*N7 -> 0 | W7: =5%*N7 -> 0 | Y7: =2.5%*N7 -> 0
N8: =K8+L8+M8 -> 0 | V8: =8%*N8 -> 0 | W8: =5%*N8 -> 0 | Y8: =2.5%*N8 -> 0
N9: =K9+L9+M9 -> 0 | V9: =8%*N9 -> 0 | W9: =5%*N9 -> 0 | Y9: =2.5%*N9 -> 0
N10: =K10+L10+M10 -> 0 | V10: =8%*N10 -> 0 | W10: =5%*N10 -> 0 | Y10: =2.5%*N10 -> 0
N11: =K11+L11+M11 -> 0 | V11: =8%*N11 -> 0 | W11: =5%*N11 -> 0 | Y11: =2.5%*N11 -> 0
N12: =K12+L12+M12 -> 0 | V12: =8%*N12 -> 0 | W12: =5%*N12 -> 0 | Y12: =2.5%*N12 -> 0
N13: =K13+L13+M13 -> 0 | V13: =8%*N13 -> 0 | W13: =5%*N13 -> 0 | Y13: =2.5%*N13 -> 0
N14: =K14+L14+M14 -> 0 | V14: =8%*N14 -> 0 | W14: =5%*N14 -> 0 | Y14: =2.5%*N14 -> 0
N15: =K15+L15+M15 -> 0 | V15: =8%*N15 -> 0 | W15: =5%*N15 -> 0 | Y15: =2.5%*N15 -> 0
N16: =K16+L16+M16 -> 0 | V16: =8%*N16 -> 0 | W16: =5%*N16 -> 0 | Y16: =2.5%*N16 -> 0
N17: =K17+L17+M17 -> 0 | V17: =8%*N17 -> 0 | W17: =5%*N17 -> 0 | Y17: =2.5%*N17 -> 0
N18: =K18+L18+M18 -> 0 | V18: =8%*N18 -> 0 | W18: =5%*N18 -> 0 | Y18: =2.5%*N18 -> 0
N19: =K19+L19+M19 -> 0 | V19: =8%*N19 -> 0 | W19: =5%*N19 -> 0 | Y19: =2.5%*N19 -> 0
... N110: =K110+L110+M110 -> 0 | V110: =8%*N110 -> 0 | W110: =5%*N110 -> 0 | Y110: =2.5%*N110 -> 0

Sheet Payroll Cost Analysis 2024
D2: Analysis of Payroll Cost - Nigerian Staff | H2: 2024
B4: S/N | C4: Employees Details | K4: Payroll Items | V4: Deductions
C5: Staff Number | D5: Last Name | E5: First Name | F5: Other Name | G5: Designation | H5: ABC - ID | I5: Location | J5: No. of Month | K5: Basic | L5: Pensionable Income | O5: Non Pensionable Income | T5: One-Off Allowances | U5: Total Pay | V5: Pensions | W5: NHIS | X5: Gratuity | Y5: NHF | Z5: Life Assurance Premium
L6: Housing | M6: Transport | N6: BHT | O6: Utility | P6: Dressing | Q6: Lunch | R6: Leave | S6: Others
B7: 1 | N7: =K7+L7+M7 -> 0 | V7: =8%*N7 -> 0 | W7: =5%*N7 -> 0 | Y7: =2.5%*N7 -> 0
N8: =K8+L8+M8 -> 0 | V8: =8%*N8 -> 0 | W8: =5%*N8 -> 0 | Y8: =2.5%*N8 -> 0
N9: =K9+L9+M9 -> 0 | V9: =8%*N9 -> 0 | W9: =5%*N9 -> 0 | Y9: =2.5%*N9 -> 0
N10: =K10+L10+M10 -> 0 | V10: =8%*N10 -> 0 | W10: =5%*N10 -> 0 | Y10: =2.5%*N10 -> 0
N11: =K11+L11+M11 -> 0 | V11: =8%*N11 -> 0 | W11: =5%*N11 -> 0 | Y11: =2.5%*N11 -> 0
N12: =K12+L12+M12 -> 0 | V12: =8%*N12 -> 0 | W12: =5%*N12 -> 0 | Y12: =2.5%*N12 -> 0
N13: =K13+L13+M13 -> 0 | V13: =8%*N13 -> 0 | W13: =5%*N13 -> 0 | Y13: =2.5%*N13 -> 0
N14: =K14+L14+M14 -> 0 | V14: =8%*N14 -> 0 | W14: =5%*N14 -> 0 | Y14: =2.5%*N14 -> 0
N15: =K15+L15+M15 -> 0 | V15: =8%*N15 -> 0 | W15: =5%*N15 -> 0 | Y15: =2.5%*N15 -> 0
N16: =K16+L16+M16 -> 0 | V16: =8%*N16 -> 0 | W16: =5%*N16 -> 0 | Y16: =2.5%*N16 -> 0
N17: =K17+L17+M17 -> 0 | V17: =8%*N17 -> 0 | W17: =5%*N17 -> 0 | Y17: =2.5%*N17 -> 0
N18: =K18+L18+M18 -> 0 | V18: =8%*N18 -> 0 | W18: =5%*N18 -> 0 | Y18: =2.5%*N18 -> 0
N19: =K19+L19+M19 -> 0 | V19: =8%*N19 -> 0 | W19: =5%*N19 -> 0 | Y19: =2.5%*N19 -> 0
... N110: =K110+L110+M110 -> 0 | V110: =8%*N110 -> 0 | W110: =5%*N110 -> 0 | Y110: =2.5%*N110 -> 0

Sheet Expatriate 2023
C2: Analysis of Payroll Cost - Expatriate | G2: 2023
A4: S/N | B4: Employees Details | K4: Payroll Items | U4: Benefits -in-kind | X4: Deductions
B5: Staff Number | C5: Last Name | D5: First Name | E5: Other Name | F5: Designation | G5: ABC - ID | H5: Location | I5: Nationality | J5: No. of Month | K5: Basic | L5: Pensionable Income | N5: Non Pensionable Income | S5: One-Off Allowances | T5: Total Pay | U5: Motor Vehicles | V5: House/Rent | W5: Other Benefits | X5: Pensions | Y5: Life Assurance | Z5: Others*
L6: Housing | M6: Transport | N6: Utility | O6: Dressing | P6: Lunch | Q6: Leave | R6: Others
Y18: * Please Specify

Sheet Expatriate 2024
C2: Analysis of Payroll Cost - Expatriate | G2: 2024
A4: S/N | B4: Employees Details | K4: Payroll Items | U4: Benefits -in-kind | X4: Deductions
B5: Staff Number | C5: Last Name | D5: First Name | E5: Other Name | F5: Designation | G5: ABC - ID | H5: Location | I5: Nationality | J5: No. of Month | K5: Basic | L5: Pensionable Income | N5: Non Pensionable Income | S5: One-Off Allowances | T5: Total Pay | U5: Motor Vehicles | V5: House/Rent | W5: Other Benefits | X5: Pensions | Y5: Life Assurance | Z5: Others*
L6: Housing | M6: Transport | N6: Utility | O6: Dressing | P6: Lunch | Q6: Leave | R6: Others
Y18: * Please Specify

Sheet WHT Schedule 2023
D2: Schedule of WHT - Payment to Individuals/Enterprises/Business Name in Lagos
C3: Transaction | E3: Payment | F3: Nature of | G3: Transaction | I3: WITHHOLDING
B4: S/N | C4: Date | D4: Names of Companies/Beneficiaries | E4: Voucher No | F4: Transaction | G4: Amount | I4: AMOUNT
B5: 1
B6: 2
B7: 3
B8: 4
B9: 5
B10: 6
B11: 7
B12: 8
B13: 9
B14: 10
B15: 11
B16: 12
... B37: 33

Sheet WHT Schedule 2024
D2: Schedule of WHT - Payment to Individuals/Enterprises/Business Name in Lagos
C3: Transaction | E3: Payment | F3: Nature of | G3: Transaction | I3: WITHHOLDING
B4: S/N | C4: Date | D4: Names of Companies/Beneficiaries | E4: Voucher No | F4: Transaction | G4: Amount | I4: AMOUNT
B5: 1
B6: 2
B7: 3
B8: 4
B9: 5
B10: 6
B11: 7
B12: 8
B13: 9
B14: 10
B15: 11
B16: 12
... B37: 33

Sheet WHT SMRY 2023
A1: LAGOS STATE GOVERNMENT
A2: NAME:
A3: WHT SUMMARY SHEET
A4: JAN-DEC : | B4: 2023
A5: Registration No ( RC ):
A6: Date of Registration:
A7: Nature of Business:
E9: 2023
C10: GROSS | D10: RATE | E10: WHT DUE
C11: N | D11: % | E11: N
B13: CONTRACT / SUPPLY | C13: 0 | D13: 0.05 | E13: =C13*0.05 -> 0
B15: LEGAL / PROF. FEES | C15: 0 | D15: 0.05 | E15: =C15*0.05 -> 0
B17: SERVICE | C17: 0 | D17: 0.05 | E17: =C17*0.05 -> 0
B19: AUDIT FEES | C19: 0 | D19: 0.05 | E19: =C19*0.05 -> 0
B21: CONSULTANCY FEE | C21: 0 | D21: 0.05 | E21: =C21*D21 -> 0
B23: DIVIDENDS | C23: 0 | D23: 0.1 | E23: =C23*0.1 -> 0
B25: DIRECTORS FEES | C25: 0 | D25: 0.1 | E25: =C25*0.1 -> 0
B27: RENT | C27: 0 | D27: 0.1 | E27: =C27*0.1 -> 0
B29: COMMISSION | C29: 0 | D29: 0.1 | E29: =C29*0.1 -> 0
C31: =SUM(C13:C30) -> 0 | E31: =SUM(E13:E30) -> 0

Sheet WHT SMRY 2024
A1: LAGOS STATE GOVERNMENT
A2: NAME:
A3: WHT SUMMARY SHEET
A4: JAN-DEC : | B4: 2024
A5: Registration No ( RC ):
A6: Date of Registration:
A7: Nature of Business:
E9: 2024 | I9: 2023
C10: GROSS | D10: RATE | E10: WHT DUE | G10: GROSS | H10: RATE | I10: WHT DUE
C11: N | D11: % | E11: N | G11: N | H11: % | I11: N
B13: CONTRACT / SUPPLY | C13: 0 | D13: 0.05 | E13: =C13*0.05 -> 0 | G13: 0 | H13: 0.05 | I13: =G13*0.05 -> 0
B15: LEGAL / PROF. FEES | C15: 0 | D15: 0.05 | E15: =C15*0.05 -> 0 | G15: 1000000 | H15: 0.05 | I15: =G15*0.05 -> 50000
B17: SERVICE | C17: 0 | D17: 0.05 | E17: =C17*0.05 -> 0 | G17: 0 | H17: 0.05 | I17: =G17*0.05 -> 0
B19: AUDIT FEES | C19: 3000000 | D19: 0.05 | E19: =C19*0.05 -> 150000 | G19: 2000000 | H19: 0.05 | I19: =G19*0.05 -> 100000
B21: CONSULTANCY FEE | C21: 0 | D21: 0.05 | E21: =C21*D21 -> 0 | G21: 0 | H21: 0.05 | I21: =G21*H21 -> 0
B23: DIVIDENDS | C23: 0 | D23: 0.1 | E23: =C23*0.1 -> 0 | G23: 0 | H23: 0.1 | I23: =G23*0.1 -> 0
B25: DIRECTORS FEES | C25: 0 | D25: 0.1 | E25: =C25*0.1 -> 0 | G25: 0 | H25: 0.1 | I25: =G25*0.1 -> 0
B27: RENT | C27: =E27*10 -> 11200000 | D27: 0.1 | E27: =+'WHT Remittance 2024'!C13 -> 1120000 | G27: =I27*10 -> 22500000 | H27: 0.1 | I27: =+'WHT Remittance 2023'!C12 -> 2250000
B29: COMMISSION | C29: 0 | D29: 0.1 | E29: =C29*0.1 -> 0 | G29: 0 | H29: 0.1 | I29: =G29*0.1 -> 0
C31: =SUM(C13:C30) -> 14200000 | E31: =SUM(E13:E30) -> 1270000 | G31: =SUM(G13:G30) -> 25500000 | I31: =SUM(I13:I30) -> 2400000

Sheet  PAYE Remittances 2023
C3: SUMMARY OF TAX REMITTANCE RECEIPT 2023 PAYE
B5: S/N | C5: Receipt No | D5: Amount | E5: Period Covered | F5: Date of Payment | G5: Bank
B6: 1 | C6: 51239606/TNMGNVUP | D6: 580200 | E6: JANUARY | F6: 22/03/2023 | G6: FCMB
B7: 2 | C7: 51239599/NRHPNMWI | D7: 585800 | E7: FEBRUARY | F7: 22/03/2023 | G7: FCMB
B8: 3 | C8: 51720496/XJYHLULI | D8: 587400 | E8: MARCH | F8: 18/03/2023 | G8: ACCESS
B9: 4 | C9: 51720513/ANLATDFZ | D9: 572300 | E9: APRIL | F9: 18/03/2023 | G9: ACCESS
B10: 5 | C10: 51941341/MVWHPLHW | D10: 577100 | E10: MAY | F10: 45175 | G10: ACCESS
B11: 6 | C11: 52216957/JUKYUZUR | D11: 574500 | E11: JUNE | F11: 45206 | G11: ACCESS
B12: 7 | C12: 52521244/ZDKBGECC | D12: 577400 | E12: JULY | F12: 45238 | G12: ACCESS
B13: 8 | C13: 52769775/CRIXGYDV | D13: 581500 | E13: AUGUST | F13: 45086 | G13: ACCESS
B14: 9 | C14: 53106832/KEPNJGDD | D14: 569500 | E14: SEPTEMBER | F14: 45056 | G14: ACCESS
B15: 10 | C15: 53433029/RZNAWYNZ | D15: 563593 | E15: OCTOBER | F15: 44996 | G15: ACCESS
B16: 11 | C16: 53819864/QJWRMQDS | D16: 562902 | E16: NOVEMBER | F16: 45272 | G16: ACCESS
B17: 12 | C17: 54023592/JAEJRYRT | D17: 562902 | E17: DECEMBER | F17: 45505 | G17: ACCESS
D18: 6895097

Sheet PAYE Remittances 2024
C3: SUMMARY OF TAX REMITTANCE RECEIPT 2024 PAYE
B5: S/N | C5: Receipt No | D5: Amount | E5: Period Covered | F5: Date of Payment | G5: Bank
B6: 1 | C6: 54409365/YKZAJTJN | D6: 545253.33 | E6: JANUARY | F6: 15/02/2024 | G6: ACCESS
B7: 2 | C7: 54725500/AYSWDGBU | D7: 545253.35 | E7: FEBRUARY | F7: 21/03/2024 | G7: ACCESS
B8: 3 | C8: 54947689/USELDNTH | D8: 546102.66 | E8: MARCH | F8: 18/04/2024 | G8: ACCESS
B9: 4 | C9: 55304724/ktlpdqii | D9: 170222 | E9: APRIL | F9: 24/05/2024 | G9: ACCESS
B10: 5 | C10: 55567069/AGMGFMUR | D10: 170300 | E10: MAY | F10: 26/06/2024 | G10: ACCESS
B11: 6 | C11: 55886106/ZANJHMKW | D11: 171071 | E11: JUNE | F11: 31/07/2024 | G11: ACCESS
B12: 7 | C12: 56037877/GYCFMTHE | D12: 170000 | E12: JULY | F12: 30/08/2024 | G12: ACCESS
B13: 8 | C13: 56151305/TAKKZCQP | D13: 166863 | E13: AUGUST | F13: 20/09/2024 | G13: ACCESS
B14: 9 | C14: 56593668/DPTVPGYG | D14: 159108 | E14: SEPTEMBER | F14: 22/10/2024 | G14: ACCESS
B15: 10 | C15: 56894697/ATFALKRE | D15: 159677 | E15: OCTOBER | F15: 25/11/2024 | G15: ACCESS
B16: 11 | C16: 57374232/DLFRLXMD | D16: 154630 | E16: NOVEMBER | F16: 45809 | G16: ACCESS
B17: 12 | C17: 57374082/DXTKHMGP | D17: 154630 | E17: DECEMBER | F17: 45809 | G17: ACCESS
D19: =SUM(D6:D18) -> 3113110.3

Sheet  Direct Assessment 2023&2024
C3: SUMMARY OF TAX REMITTANCE RECEIPT DIRECT ASSESSMENT 2023
B5: S/N | C5: Receipt No | D5: Amount | E5: Period Covered | F5: Date of Payment | G5: Bank
B6: 1 | C6: 55787462/DRPSPEWA | D6: 245980 | E6: JANUARY | F6: 19/07/2024 | G6: ZENITH
E7: FEBRUARY
E8: MARCH
C11: SUMMARY OF TAX REMITTANCE RECEIPT DIRECT ASSESSMENT 2024
B13: S/N | C13: Receipt No | D13: Amount | E13: Period Covered | F13: Date of Payment | G13: Bank
B14: 1 | C14: 58360132/CEQCZLDV | D14: 280000 | E14: JANUARY | F14: 30/04/2025 | G14: ZENITH
E15: FEBRUARY
E16: MARCH

Sheet WHT Remittance 2023
B2: SCHEDULE OF WITHHOLDING TAX REMITTANCES
B4: S/N | C4: Amount Paid | D4: Period Covered | E4: Date of Payment | F4: Receipt No | G4: Nature of Transaction | H4: Bank
B5: 1 | C5: 150000 | D5: JANUARY | E5: 18/01/2024 | F5: 54095484/DPFVLCSA | G5: RENT | H5: ACCESS
B6: 2 | C6: 800000 | D6: FEBRUARY | E6: 18/01/2024 | F6: 54095437/CYYZHVGS | G6: RENT | H6: ACCESS
B7: 3 | C7: 300000 | D7: MARCH | E7: 18/01/2024 | F7: 5409543/VRBJIRSE | G7: RENT | H7: ACCESS
B8: 4 | C8: 250000 | D8: APRIL | E8: 18/01/2024 | F8: 54095452/UVKVHHVE | G8: RENT | H8: ACCESS
B9: 5 | C9: 300000 | D9: MAY | E9: 18/01/2024 | F9: 54095465/GXTSGMJB | G9: RENT | H9: ACCESS
B10: 6 | C10: 300000 | D10: JUNE | E10: 18/01/2024 | F10: 54095490/FSVKKYTF | G10: RENT | H10: ACCESS
B11: 7 | C11: 150000 | D11: JULY | E11: 18/01/2024 | F11: 54095484/DPFVLCSA | G11: RENT | H11: ACCESS
C12: 2250000

Sheet WHT Remittance 2024
B2: SCHEDULE OF WITHHOLDING TAX REMITTANCES
B4: S/N | C4: Amount Paid | D4: Period Covered | E4: Date of Payment | F4: Receipt No | G4: Nature of Transaction | H4: Bank
B5: 1 | C5: 140000 | D5: JANUARY | E5: 16/01/2025 | F5: 57457377/WRFJFADY | G5: RENT | H5: ACCESS
B6: 2 | C6: 90000 | D6: FEBRUARY | E6: 16/01/2025 | F6: 57457850/BRFVLEJQ | G6: RENT | H6: ACCESS
B7: 3 | C7: 250000 | D7: MARCH | E7: 16/01/2025 | F7: 57457863/VKLPYIXN | G7: RENT | H7: ACCESS
B8: 4 | C8: 150000 | D8: APRIL | E8: 16/01/2025 | F8: 57458222/UZGXZPCK | G8: RENT | H8: ACCESS
B9: 5 | C9: 300000 | D9: MAY | E9: 16/01/2025 | F9: 57458218/NYBPWCA | G9: RENT | H9: ACCESS
B10: 6 | C10: 100000 | D10: JUNE | E10: 16/01/2025 | F10: 57457832/UWTNFLPA | G10: RENT | H10: ACCESS
B11: 7 | C11: 90000 | D11: JULY | E11: 16/01/2025 | F11: 57457370/DRPYJLXH | G11: RENT | H11: ACCESS
C13: =SUM(C5:C12) -> 1120000

Sheet Biz Premises 2023
C6: BUSINESS/OFFICE LOCATIONS OF TAX PAYER IN LAGOS
B9: S/N | C9: Office/Location Address | D9: Amount Due | E9: Amount Paid | F9: Period Covered | G9: Receipt NO
B10: 1 | C10: 20, OBAFEMI AWOLOWA WAY, IKEJA, LAGOS | D10: 5000 | E10: 5000 | F10: 2023 | G10: 54091900/VCPBKLDM

Sheet Biz Premises 2024
C6: BUSINESS/OFFICE LOCATIONS OF TAX PAYER IN LAGOS
B9: S/N | C9: Office/Location Address | D9: Amount Due | E9: Amount Paid | F9: Period Covered | G9: Receipt NO
B10: 1 | C10: 20, OBAFEMI AWOLOWA WAY, IKEJA, LAGOS | D10: 5000 | E10: 5000 | F10: 2024 | G10: 57512568/GYNHYVYI

Sheet Development Levy 2023
B3: Schedule of Development Levy Remittances LOCAL 2023
A6: S/N | B6: Amount Due | C6: Amount Paid | D6: Period Covered | E6: Date of Payment | F6: Receipt NO
A7: 1 | C7: 14000 | D7: 2023 | E7: 45505 | F7: 54023607/LAEGGADY
B15: Schedule of Development Levy Remittances EXPATRAITE 2023
A18: S/N | B18: Amount Due | C18: Amount Paid | D18: Period Covered | E18: Date of Payment | F18: Receipt NO
A19: 1 | D19: 2023

Sheet Development Levy 2024
B3: Schedule of Development Levy Remittances LOCAL 2024
A6: S/N | B6: Amount Due | C6: Amount Paid | D6: Period Covered | E6: Date of Payment | F6: Receipt NO
A7: 1 | C7: 10700 | D7: 2024 | E7: 21/01/2025 | F7: 57506423/SYVKXDFH
B14: Schedule of Development Levy Remittances EXPATRAITE 2024
A17: S/N | B17: Amount Due | C17: Amount Paid | D17: Period Covered | E17: Date of Payment | F17: Receipt NO
A18: 1 | B18: 500 | C18: 500 | D18: 2024 | E18: 21/01/2025 | F18: 57506990/WVNHMFVR

Sheet computation (local) 2021
A7: S/N | B7: NAME | C7: DESIGNATION | D7: ANNUAL TOTAL GROSS INCOME + BIK | E7: PENSION | F7: NET INCOME | G7: CRA | H7: TAXABLE INCOME | I7: ANNUAL TAX | J7: MONTHLY TAX | K7: MNTH | L7: PRO BY MNTH
A8: 1 | E8: =D8*0.08 -> 0 | F8: =D8-E8 -> 0 | G8: =IF(F8<=300000,0,IF(F8>=20000000,(F8*0.21),(F8*0.2)+200000)) -> 0 | H8: =+D8-G8-E8 -> 0 | I8: =IF(G8=0,(D8*0.01),IF(H8<=0,0.01*D8,IF(AND(H8>0,H8<=300000),H8*7%,IF(AND(H8>=300000,H8<600000),21000+(H8-300000)*11%,IF(AND(H8>=600000,H8<1100000),54000+(H8-600000)*15%,IF(AND(H8>=1100000,H8<1600000),129000+(H8-1100000)*19%,IF(AND(H8>=1600000,H8<3200000),224000+(H8-1600000)*21%,560000+(H8-3200000)*24%))))))) -> 0 | J8: =I8/12 -> 0 | K8: 12 | L8: =+J8*K8 -> 0
A9: 2 | D9: 0 | E9: =D9*0.08 -> 0 | F9: =D9-E9 -> 0 | G9: =IF(F9<=300000,0,IF(F9>=20000000,(F9*0.21),(F9*0.2)+200000)) -> 0 | H9: =+D9-G9-E9 -> 0 | I9: =IF(G9=0,(D9*0.01),IF(H9<=0,0.01*D9,IF(AND(H9>0,H9<=300000),H9*7%,IF(AND(H9>=300000,H9<600000),21000+(H9-300000)*11%,IF(AND(H9>=600000,H9<1100000),54000+(H9-600000)*15%,IF(AND(H9>=1100000,H9<1600000),129000+(H9-1100000)*19%,IF(AND(H9>=1600000,H9<3200000),224000+(H9-1600000)*21%,560000+(H9-3200000)*24%))))))) -> 0 | J9: =I9/12 -> 0 | K9: 0 | L9: =+J9*K9 -> 0
A10: 3 | D10: 0 | E10: =D10*0.08 -> 0 | F10: =D10-E10 -> 0 | G10: =IF(F10<=300000,0,IF(F10>=20000000,(F10*0.21),(F10*0.2)+200000)) -> 0 | H10: =+D10-G10-E10 -> 0 | I10: =IF(G10=0,(D10*0.01),IF(H10<=0,0.01*D10,IF(AND(H10>0,H10<=300000),H10*7%,IF(AND(H10>=300000,H10<600000),21000+(H10-300000)*11%,IF(AND(H10>=600000,H10<1100000),54000+(H10-600000)*15%,IF(AND(H10>=1100000,H10<1600000),129000+(H10-1100000)*19%,IF(AND(H10>=1600000,H10<3200000),224000+(H10-1600000)*21%,560000+(H10-3200000)*24%))))))) -> 0 | J10: =I10/12 -> 0 | K10: 0 | L10: =+J10*K10 -> 0
A11: 4 | D11: 0 | E11: =D11*0.08 -> 0 | F11: =D11-E11 -> 0 | G11: =IF(F11<=300000,0,IF(F11>=20000000,(F11*0.21),(F11*0.2)+200000)) -> 0 | H11: =+D11-G11-E11 -> 0 | I11: =IF(G11=0,(D11*0.01),IF(H11<=0,0.01*D11,IF(AND(H11>0,H11<=300000),H11*7%,IF(AND(H11>=300000,H11<600000),21000+(H11-300000)*11%,IF(AND(H11>=600000,H11<1100000),54000+(H11-600000)*15%,IF(AND(H11>=1100000,H11<1600000),129000+(H11-1100000)*19%,IF(AND(H11>=1600000,H11<3200000),224000+(H11-1600000)*21%,560000+(H11-3200000)*24%))))))) -> 0 | J11: =I11/12 -> 0 | K11: 0 | L11: =+J11*K11 -> 0
A12: 5 | D12: 0 | E12: =D12*0.08 -> 0 | F12: =D12-E12 -> 0 | G12: =IF(F12<=300000,0,IF(F12>=20000000,(F12*0.21),(F12*0.2)+200000)) -> 0 | H12: =+D12-G12-E12 -> 0 | I12: =IF(G12=0,(D12*0.01),IF(H12<=0,0.01*D12,IF(AND(H12>0,H12<=300000),H12*7%,IF(AND(H12>=300000,H12<600000),21000+(H12-300000)*11%,IF(AND(H12>=600000,H12<1100000),54000+(H12-600000)*15%,IF(AND(H12>=1100000,H12<1600000),129000+(H12-1100000)*19%,IF(AND(H12>=1600000,H12<3200000),224000+(H12-1600000)*21%,560000+(H12-3200000)*24%))))))) -> 0 | J12: =I12/12 -> 0 | K12: 0 | L12: =+J12*K12 -> 0
A13: 6 | D13: 0 | E13: =D13*0.08 -> 0 | F13: =D13-E13 -> 0 | G13: =IF(F13<=300000,0,IF(F13>=20000000,(F13*0.21),(F13*0.2)+200000)) -> 0 | H13: =+D13-G13-E13 -> 0 | I13: =IF(G13=0,(D13*0.01),IF(H13<=0,0.01*D13,IF(AND(H13>0,H13<=300000),H13*7%,IF(AND(H13>=300000,H13<600000),21000+(H13-300000)*11%,IF(AND(H13>=600000,H13<1100000),54000+(H13-600000)*15%,IF(AND(H13>=1100000,H13<1600000),129000+(H13-1100000)*19%,IF(AND(H13>=1600000,H13<3200000),224000+(H13-1600000)*21%,560000+(H13-3200000)*24%))))))) -> 0 | J13: =I13/12 -> 0 | K13: 0 | L13: =+J13*K13 -> 0
A14: 7 | D14: 0 | E14: =D14*0.08 -> 0 | F14: =D14-E14 -> 0 | G14: =IF(F14<=300000,0,IF(F14>=20000000,(F14*0.21),(F14*0.2)+200000)) -> 0 | H14: =+D14-G14-E14 -> 0 | I14: =IF(G14=0,(D14*0.01),IF(H14<=0,0.01*D14,IF(AND(H14>0,H14<=300000),H14*7%,IF(AND(H14>=300000,H14<600000),21000+(H14-300000)*11%,IF(AND(H14>=600000,H14<1100000),54000+(H14-600000)*15%,IF(AND(H14>=1100000,H14<1600000),129000+(H14-1100000)*19%,IF(AND(H14>=1600000,H14<3200000),224000+(H14-1600000)*21%,560000+(H14-3200000)*24%))))))) -> 0 | J14: =I14/12 -> 0 | K14: 0 | L14: =+J14*K14 -> 0
A15: 8 | D15: 0 | E15: =D15*0.08 -> 0 | F15: =D15-E15 -> 0 | G15: =IF(F15<=300000,0,IF(F15>=20000000,(F15*0.21),(F15*0.2)+200000)) -> 0 | H15: =+D15-G15-E15 -> 0 | I15: =IF(G15=0,(D15*0.01),IF(H15<=0,0.01*D15,IF(AND(H15>0,H15<=300000),H15*7%,IF(AND(H15>=300000,H15<600000),21000+(H15-300000)*11%,IF(AND(H15>=600000,H15<1100000),54000+(H15-600000)*15%,IF(AND(H15>=1100000,H15<1600000),129000+(H15-1100000)*19%,IF(AND(H15>=1600000,H15<3200000),224000+(H15-1600000)*21%,560000+(H15-3200000)*24%))))))) -> 0 | J15: =I15/12 -> 0 | K15: 0 | L15: =+J15*K15 -> 0
A16: 9 | D16: 0 | E16: =D16*0.08 -> 0 | F16: =D16-E16 -> 0 | G16: =IF(F16<=300000,0,IF(F16>=20000000,(F16*0.21),(F16*0.2)+200000)) -> 0 | H16: =+D16-G16-E16 -> 0 | I16: =IF(G16=0,(D16*0.01),IF(H16<=0,0.01*D16,IF(AND(H16>0,H16<=300000),H16*7%,IF(AND(H16>=300000,H16<600000),21000+(H16-300000)*11%,IF(AND(H16>=600000,H16<1100000),54000+(H16-600000)*15%,IF(AND(H16>=1100000,H16<1600000),129000+(H16-1100000)*19%,IF(AND(H16>=1600000,H16<3200000),224000+(H16-1600000)*21%,560000+(H16-3200000)*24%))))))) -> 0 | J16: =I16/12 -> 0 | K16: 0 | L16: =+J16*K16 -> 0
A17: 10 | D17: 0 | E17: =D17*0.08 -> 0 | F17: =D17-E17 -> 0 | G17: =IF(F17<=300000,0,IF(F17>=20000000,(F17*0.21),(F17*0.2)+200000)) -> 0 | H17: =+D17-G17-E17 -> 0 | I17: =IF(G17=0,(D17*0.01),IF(H17<=0,0.01*D17,IF(AND(H17>0,H17<=300000),H17*7%,IF(AND(H17>=300000,H17<600000),21000+(H17-300000)*11%,IF(AND(H17>=600000,H17<1100000),54000+(H17-600000)*15%,IF(AND(H17>=1100000,H17<1600000),129000+(H17-1100000)*19%,IF(AND(H17>=1600000,H17<3200000),224000+(H17-1600000)*21%,560000+(H17-3200000)*24%))))))) -> 0 | J17: =I17/12 -> 0 | K17: 0 | L17: =+J17*K17 -> 0
A18: 11 | D18: 0 | E18: =D18*0.08 -> 0 | F18: =D18-E18 -> 0 | G18: =IF(F18<=300000,0,IF(F18>=20000000,(F18*0.21),(F18*0.2)+200000)) -> 0 | H18: =+D18-G18-E18 -> 0 | I18: =IF(G18=0,(D18*0.01),IF(H18<=0,0.01*D18,IF(AND(H18>0,H18<=300000),H18*7%,IF(AND(H18>=300000,H18<600000),21000+(H18-300000)*11%,IF(AND(H18>=600000,H18<1100000),54000+(H18-600000)*15%,IF(AND(H18>=1100000,H18<1600000),129000+(H18-1100000)*19%,IF(AND(H18>=1600000,H18<3200000),224000+(H18-1600000)*21%,560000+(H18-3200000)*24%))))))) -> 0 | J18: =I18/12 -> 0 | K18: 0 | L18: =+J18*K18 -> 0
A19: 12 | D19: 0 | E19: =D19*0.08 -> 0 | F19: =D19-E19 -> 0 | G19: =IF(F19<=300000,0,IF(F19>=20000000,(F19*0.21),(F19*0.2)+200000)) -> 0 | H19: =+D19-G19-E19 -> 0 | I19: =IF(G19=0,(D19*0.01),IF(H19<=0,0.01*D19,IF(AND(H19>0,H19<=300000),H19*7%,IF(AND(H19>=300000,H19<600000),21000+(H19-300000)*11%,IF(AND(H19>=600000,H19<1100000),54000+(H19-600000)*15%,IF(AND(H19>=1100000,H19<1600000),129000+(H19-1100000)*19%,IF(AND(H19>=1600000,H19<3200000),224000+(H19-1600000)*21%,560000+(H19-3200000)*24%))))))) -> 0 | J19: =I19/12 -> 0 | K19: 0 | L19: =+J19*K19 -> 0
A20: 13 | D20: 0 | E20: =D20*0.08 -> 0 | F20: =D20-E20 -> 0 | G20: =IF(F20<=300000,0,IF(F20>=20000000,(F20*0.21),(F20*0.2)+200000)) -> 0 | H20: =+D20-G20-E20 -> 0 | I20: =IF(G20=0,(D20*0.01),IF(H20<=0,0.01*D20,IF(AND(H20>0,H20<=300000),H20*7%,IF(AND(H20>=300000,H20<600000),21000+(H20-300000)*11%,IF(AND(H20>=600000,H20<1100000),54000+(H20-600000)*15%,IF(AND(H20>=1100000,H20<1600000),129000+(H20-1100000)*19%,IF(AND(H20>=1600000,H20<3200000),224000+(H20-1600000)*21%,560000+(H20-3200000)*24%))))))) -> 0 | J20: =I20/12 -> 0 | K20: 0 | L20: =+J20*K20 -> 0
... A683: 676 | D683: 0 | E683: =D683*0.08 -> 0 | F683: =D683-E683 -> 0 | G683: =IF(F683<=300000,0,IF(F683>=20000000,(F683*0.21),(F683*0.2)+200000)) -> 0 | H683: =+D683-G683-E683 -> 0 | I683: =IF(G683=0,(D683*0.01),IF(H683<=0,0.01*D683,IF(AND(H683>0,H683<=300000),H683*7%,IF(AND(H683>=300000,H683<600000),21000+(H683-300000)*11%,IF(AND(H683>=600000,H683<1100000),54000+(H683-600000)*15%,IF(AND(H683>=1100000,H683<1600000),129000+(H683-1100000)*19%,IF(AND(H683>=1600000,H683<3200000),224000+(H683-1600000)*21%,560000+(H683-3200000)*24%))))))) -> 0 | J683: =I683/12 -> 0 | K683: 0 | L683: =+J683*K683 -> 0
D685: =SUM(D8:D683) -> 0 | G685: =SUM(G8:G683) -> 0 | H685: =SUM(H8:H683) -> 0 | I685: =SUM(I8:I683) -> 0 | J685: =SUM(J8:J683) -> 0 | L685: =SUM(L8:L683) -> 0

Sheet computation (expat) 2021
A7: S/N | B7: NAME | C7: DESIGNATION | D7: ANNUAL TOTAL GROSS INCOME + BIK | E7: CRA | F7: TAXABLE INCOME | G7: ANNUAL TAX | H7: MONTHLY TAX | I7: MNTH | J7: PRO BY MNTH
A8: 1 | D8: 0 | E8: =IF(D8<=300000,0,IF(D8>=20000000,(D8*0.21),(D8*0.2)+200000)) -> 0 | F8: =+D8-E8 -> 0 | G8: =IF(E8=0,(D8*0.01),IF(F8<=0,0.01*D8,IF(AND(F8>0,F8<=300000),F8*7%,IF(AND(F8>=300000,F8<600000),21000+(F8-300000)*11%,IF(AND(F8>=600000,F8<1100000),54000+(F8-600000)*15%,IF(AND(F8>=1100000,F8<1600000),129000+(F8-1100000)*19%,IF(AND(F8>=1600000,F8<3200000),224000+(F8-1600000)*21%,560000+(F8-3200000)*24%))))))) -> 0 | H8: =G8/12 -> 0 | I8: 12 | J8: =+H8*I8 -> 0
A9: 2 | D9: 0 | E9: =IF(D9<=300000,0,IF(D9>=20000000,(D9*0.21),(D9*0.2)+200000)) -> 0 | F9: =+D9-E9 -> 0 | G9: =IF(E9=0,(D9*0.01),IF(F9<=0,0.01*D9,IF(AND(F9>0,F9<=300000),F9*7%,IF(AND(F9>=300000,F9<600000),21000+(F9-300000)*11%,IF(AND(F9>=600000,F9<1100000),54000+(F9-600000)*15%,IF(AND(F9>=1100000,F9<1600000),129000+(F9-1100000)*19%,IF(AND(F9>=1600000,F9<3200000),224000+(F9-1600000)*21%,560000+(F9-3200000)*24%))))))) -> 0 | H9: =G9/12 -> 0 | I9: 0 | J9: =+H9*I9 -> 0
A10: 3 | D10: 0 | E10: =IF(D10<=300000,0,IF(D10>=20000000,(D10*0.21),(D10*0.2)+200000)) -> 0 | F10: =+D10-E10 -> 0 | G10: =IF(E10=0,(D10*0.01),IF(F10<=0,0.01*D10,IF(AND(F10>0,F10<=300000),F10*7%,IF(AND(F10>=300000,F10<600000),21000+(F10-300000)*11%,IF(AND(F10>=600000,F10<1100000),54000+(F10-600000)*15%,IF(AND(F10>=1100000,F10<1600000),129000+(F10-1100000)*19%,IF(AND(F10>=1600000,F10<3200000),224000+(F10-1600000)*21%,560000+(F10-3200000)*24%))))))) -> 0 | H10: =G10/12 -> 0 | I10: 0 | J10: =+H10*I10 -> 0
A11: 4 | D11: 0 | E11: =IF(D11<=300000,0,IF(D11>=20000000,(D11*0.21),(D11*0.2)+200000)) -> 0 | F11: =+D11-E11 -> 0 | G11: =IF(E11=0,(D11*0.01),IF(F11<=0,0.01*D11,IF(AND(F11>0,F11<=300000),F11*7%,IF(AND(F11>=300000,F11<600000),21000+(F11-300000)*11%,IF(AND(F11>=600000,F11<1100000),54000+(F11-600000)*15%,IF(AND(F11>=1100000,F11<1600000),129000+(F11-1100000)*19%,IF(AND(F11>=1600000,F11<3200000),224000+(F11-1600000)*21%,560000+(F11-3200000)*24%))))))) -> 0 | H11: =G11/12 -> 0 | I11: 0 | J11: =+H11*I11 -> 0
A12: 5 | D12: 0 | E12: =IF(D12<=300000,0,IF(D12>=20000000,(D12*0.21),(D12*0.2)+200000)) -> 0 | F12: =+D12-E12 -> 0 | G12: =IF(E12=0,(D12*0.01),IF(F12<=0,0.01*D12,IF(AND(F12>0,F12<=300000),F12*7%,IF(AND(F12>=300000,F12<600000),21000+(F12-300000)*11%,IF(AND(F12>=600000,F12<1100000),54000+(F12-600000)*15%,IF(AND(F12>=1100000,F12<1600000),129000+(F12-1100000)*19%,IF(AND(F12>=1600000,F12<3200000),224000+(F12-1600000)*21%,560000+(F12-3200000)*24%))))))) -> 0 | H12: =G12/12 -> 0 | I12: 0 | J12: =+H12*I12 -> 0
A13: 6 | D13: 0 | E13: =IF(D13<=300000,0,IF(D13>=20000000,(D13*0.21),(D13*0.2)+200000)) -> 0 | F13: =+D13-E13 -> 0 | G13: =IF(E13=0,(D13*0.01),IF(F13<=0,0.01*D13,IF(AND(F13>0,F13<=300000),F13*7%,IF(AND(F13>=300000,F13<600000),21000+(F13-300000)*11%,IF(AND(F13>=600000,F13<1100000),54000+(F13-600000)*15%,IF(AND(F13>=1100000,F13<1600000),129000+(F13-1100000)*19%,IF(AND(F13>=1600000,F13<3200000),224000+(F13-1600000)*21%,560000+(F13-3200000)*24%))))))) -> 0 | H13: =G13/12 -> 0 | I13: 0 | J13: =+H13*I13 -> 0
A14: 7 | D14: 0 | E14: =IF(D14<=300000,0,IF(D14>=20000000,(D14*0.21),(D14*0.2)+200000)) -> 0 | F14: =+D14-E14 -> 0 | G14: =IF(E14=0,(D14*0.01),IF(F14<=0,0.01*D14,IF(AND(F14>0,F14<=300000),F14*7%,IF(AND(F14>=300000,F14<600000),21000+(F14-300000)*11%,IF(AND(F14>=600000,F14<1100000),54000+(F14-600000)*15%,IF(AND(F14>=1100000,F14<1600000),129000+(F14-1100000)*19%,IF(AND(F14>=1600000,F14<3200000),224000+(F14-1600000)*21%,560000+(F14-3200000)*24%))))))) -> 0 | H14: =G14/12 -> 0 | I14: 0 | J14: =+H14*I14 -> 0
A15: 8 | D15: 0 | E15: =IF(D15<=300000,0,IF(D15>=20000000,(D15*0.21),(D15*0.2)+200000)) -> 0 | F15: =+D15-E15 -> 0 | G15: =IF(E15=0,(D15*0.01),IF(F15<=0,0.01*D15,IF(AND(F15>0,F15<=300000),F15*7%,IF(AND(F15>=300000,F15<600000),21000+(F15-300000)*11%,IF(AND(F15>=600000,F15<1100000),54000+(F15-600000)*15%,IF(AND(F15>=1100000,F15<1600000),129000+(F15-1100000)*19%,IF(AND(F15>=1600000,F15<3200000),224000+(F15-1600000)*21%,560000+(F15-3200000)*24%))))))) -> 0 | H15: =G15/12 -> 0 | I15: 0 | J15: =+H15*I15 -> 0
A16: 9 | D16: 0 | E16: =IF(D16<=300000,0,IF(D16>=20000000,(D16*0.21),(D16*0.2)+200000)) -> 0 | F16: =+D16-E16 -> 0 | G16: =IF(E16=0,(D16*0.01),IF(F16<=0,0.01*D16,IF(AND(F16>0,F16<=300000),F16*7%,IF(AND(F16>=300000,F16<600000),21000+(F16-300000)*11%,IF(AND(F16>=600000,F16<1100000),54000+(F16-600000)*15%,IF(AND(F16>=1100000,F16<1600000),129000+(F16-1100000)*19%,IF(AND(F16>=1600000,F16<3200000),224000+(F16-1600000)*21%,560000+(F16-3200000)*24%))))))) -> 0 | H16: =G16/12 -> 0 | I16: 0 | J16: =+H16*I16 -> 0
A17: 10 | D17: 0 | E17: =IF(D17<=300000,0,IF(D17>=20000000,(D17*0.21),(D17*0.2)+200000)) -> 0 | F17: =+D17-E17 -> 0 | G17: =IF(E17=0,(D17*0.01),IF(F17<=0,0.01*D17,IF(AND(F17>0,F17<=300000),F17*7%,IF(AND(F17>=300000,F17<600000),21000+(F17-300000)*11%,IF(AND(F17>=600000,F17<1100000),54000+(F17-600000)*15%,IF(AND(F17>=1100000,F17<1600000),129000+(F17-1100000)*19%,IF(AND(F17>=1600000,F17<3200000),224000+(F17-1600000)*21%,560000+(F17-3200000)*24%))))))) -> 0 | H17: =G17/12 -> 0 | I17: 0 | J17: =+H17*I17 -> 0
A18: 11 | D18: 0 | E18: =IF(D18<=300000,0,IF(D18>=20000000,(D18*0.21),(D18*0.2)+200000)) -> 0 | F18: =+D18-E18 -> 0 | G18: =IF(E18=0,(D18*0.01),IF(F18<=0,0.01*D18,IF(AND(F18>0,F18<=300000),F18*7%,IF(AND(F18>=300000,F18<600000),21000+(F18-300000)*11%,IF(AND(F18>=600000,F18<1100000),54000+(F18-600000)*15%,IF(AND(F18>=1100000,F18<1600000),129000+(F18-1100000)*19%,IF(AND(F18>=1600000,F18<3200000),224000+(F18-1600000)*21%,560000+(F18-3200000)*24%))))))) -> 0 | H18: =G18/12 -> 0 | I18: 0 | J18: =+H18*I18 -> 0
A19: 12 | D19: 0 | E19: =IF(D19<=300000,0,IF(D19>=20000000,(D19*0.21),(D19*0.2)+200000)) -> 0 | F19: =+D19-E19 -> 0 | G19: =IF(E19=0,(D19*0.01),IF(F19<=0,0.01*D19,IF(AND(F19>0,F19<=300000),F19*7%,IF(AND(F19>=300000,F19<600000),21000+(F19-300000)*11%,IF(AND(F19>=600000,F19<1100000),54000+(F19-600000)*15%,IF(AND(F19>=1100000,F19<1600000),129000+(F19-1100000)*19%,IF(AND(F19>=1600000,F19<3200000),224000+(F19-1600000)*21%,560000+(F19-3200000)*24%))))))) -> 0 | H19: =G19/12 -> 0 | I19: 0 | J19: =+H19*I19 -> 0
... A683: 676 | D683: 0 | E683: =IF(D683<=300000,0,IF(D683>=20000000,(D683*0.21),(D683*0.2)+200000)) -> 0 | F683: =+D683-E683 -> 0 | G683: =IF(E683=0,(D683*0.01),IF(F683<=0,0.01*D683,IF(AND(F683>0,F683<=300000),F683*7%,IF(AND(F683>=300000,F683<600000),21000+(F683-300000)*11%,IF(AND(F683>=600000,F683<1100000),54000+(F683-600000)*15%,IF(AND(F683>=1100000,F683<1600000),129000+(F683-1100000)*19%,IF(AND(F683>=1600000,F683<3200000),224000+(F683-1600000)*21%,560000+(F683-3200000)*24%))))))) -> 0 | H683: =G683/12 -> 0 | I683: 0 | J683: =+H683*I683 -> 0
D685: =SUM(D8:D683) -> 0 | E685: =SUM(E8:E683) -> 0 | F685: =SUM(F8:F683) -> 0 | G685: =SUM(G8:G683) -> 0 | H685: =SUM(H8:H683) -> 0 | J685: =SUM(J8:J683) -> 0

Sheet Tax Due (2)
B1: 3c
C3: 2023 | D3: 2024 | E3: TOTAL
B4: PAYE
B5: Tax Liability:
B6: Local | C6: =+'local 23'!U127 -> 3423008 | D6: =+'local 24'!T128 -> 3378841.6 | E6: =SUM(C6:D6) -> 6801849.6
B7: Expatriate | C7: =+'expat 2023'!R8 -> 5632000 | D7: =+'expat 2024 '!Q8 -> 6208000 | E7: =SUM(C7:D7) -> 11840000
B8: Total PAYE liability | C8: =C6+C7 -> 9055008 | D8: =D6+D7 -> 9586841.6 | E8: =SUM(C8:D8) -> 18641850
B10: Remittances
B11: Local & Exp. | C11: 7141077 | D11: 6753847.3 | E11: =SUM(C11:D11) -> 13894924
B12: Total Remittances | C12: =C11 -> 7141077 | D12: =D11 -> 6753847.3 | E12: =SUM(C12:D12) -> 13894924
B14: Total PAYE Outstand'g Remit'nces | C14: =C8-C12 -> 1913931 | D14: =D8-D12 -> 2832994.3 | E14: =SUM(C14:D14) -> 4746925.3
B16: WHT
B17: Directors' Fees | C17: 0 | D17: 0 | E17: =SUM(C17:D17) -> 0
B18: Rent | C18: =+'WHT SMRY 2024'!E27 -> 1120000 | D18: =+'WHT SMRY 2024'!I27 -> 2250000 | E18: =SUM(C18:D18) -> 3370000
B19: Services | C19: 0 | D19: 0 | E19: =SUM(C19:D19) -> 0
B20: Legal & Prof Fees | C20: =+'WHT SMRY 2024'!I15 -> 50000 | D20: 0 | E20: =SUM(C20:D20) -> 50000
B21: Audit Fees | C21: =+'WHT SMRY 2024'!I19 -> 100000 | D21: =+'WHT SMRY 2024'!E19 -> 150000 | E21: =SUM(C21:D21) -> 250000
B22: Contract & Supply | D22: 0 | E22: =SUM(C22:D22) -> 0
B23: Dividend | C23: 0 | D23: 0 | E23: =SUM(C23:D23) -> 0
B24: Commission | C24: ='[55]WHT SMRY'!E27 -> 0 | D24: ='[55]WHT SMRY'!H27 -> 0 | E24: =SUM(C24:D24) -> 0
B25: Sub-Total | C25: =SUM(C17:C24) -> 1270000 | D25: =SUM(D17:D24) -> 2400000 | E25: =SUM(C25:D25) -> 3670000
B26: Less: Remittances | C26: =+'WHT Remittance 2024'!C13 -> 1120000 | D26: =+'WHT Remittance 2023'!C12 -> 2250000 | E26: =SUM(C26:D26) -> 3370000
B27: Total WHT Outstanding | C27: =C25-C26 -> 150000 | D27: =D25-D26 -> 150000 | E27: =SUM(C27:D27) -> 300000
E28: =SUM(C28:D28) -> 0
B29: PAYE & WHT Outst'dg | C29: =C14+C27 -> 2063931 | D29: =D14+D27 -> 2982994.3 | E29: =SUM(C29:D29) -> 5046925.3
B30: Development Levy | C30: 0 | D30: 0 | E30: =SUM(C30:D30) -> 0
B31: Business Premises | C31: 0 | D31: 0 | E31: =SUM(C31:D31) -> 0
B32: Sub-Total | C32: =SUM(C29:C31) -> 2063931 | D32: =SUM(D29:D31) -> 2982994.3 | E32: =SUM(C32:D32) -> 5046925.3
B33: Add: 10% Penalty | C33: =IF(C32<0,0,(0.1*C32)) -> 206393.1 | D33: =IF(D32<0,0,(0.1*D32)) -> 298299.43 | E33: =SUM(C33:D33) -> 504692.53
C34: =SUM(C32:C33) -> 2270324.1 | D34: =SUM(D32:D33) -> 3281293.7 | E34: =SUM(C34:D34) -> 5551617.8
B35: Add: 12% Interest on WHT | C35: =0.12*C27 -> 18000 | D35: =0.12*D27 -> 18000 | E35: =SUM(C35:D35) -> 36000
B36: Add: 21% Interest | C36: =0.21*(C14+C30+C31) -> 401925.51 | D36: =0.21*(D14+D30+D31) -> 594928.79 | E36: =SUM(C36:D36) -> 996854.3
B37: TOTAL AMOUNT DUE | C37: =SUM(C34:C36) -> 2690249.6 | D37: =SUM(D34:D36) -> 3894222.5 | E37: =SUM(C37:D37) -> 6584472.1

Sheet local 23
A1: 3C HUB BRAND MANAGEMENT LIMITED
A2: ANNUAL PAYROLL FOR 2023
A3: NO OF EMPLOYEE | B3: Tax Payer Number | C3: Surname | D3: First Name | E3: Middle Name | F3: Designation | G3: No. of Months | H3: Gross Income | I3: Chargeable Income | J3: Development Levy | K3: Tax Paid | M3: ANNUAL TOTAL GROSS INCOME + BIK | N3: PENSION | O3: NET INCOME | P3: CRA | Q3: TAXABLE INCOME | R3: ANNUAL TAX | S3: MONTHLY TAX | T3: MNTH | U3: PRO BY MNTH
A4: 1 | B4: N-10811847 | C4: Ihezie | D4: Monica | F4: 020 Officer | G4: 12 | H4: 540000 | I4: 188800 | J4: 100 | K4: 13216 | M4: =H4 -> 540000 | N4: =M4*0.08 -> 43200 | O4: =M4-N4 -> 496800 | P4: =IF(O4<=300000,0,IF(O4>=20000000,(O4*0.21),(O4*0.2)+200000)) -> 299360 | Q4: =+M4-P4-N4 -> 197440 | R4: =IF(P4=0,(M4*0.01),IF(Q4<=0,0.01*M4,IF(AND(Q4>0,Q4<=300000),Q4*7%,IF(AND(Q4>=300000,Q4<600000),21000+(Q4-300000)*11%,IF(AND(Q4>=600000,Q4<1100000),54000+(Q4-600000)*15%,IF(AND(Q4>=1100000,Q4<1600000),129000+(Q4-1100000)*19%,IF(AND(Q4>=1600000,Q4<3200000),224000+(Q4-1600000)*21%,560000+(Q4-3200000)*24%))))))) -> 13820.8 | S4: =R4/12 -> 1151.7333 | T4: =G4 -> 12 | U4: =+S4*T4 -> 13820.8
A5: 2 | B5: N-2986347 | C5: Victor. | D5: N. | E5: Nwaoha | F5: Info Tech | G5: 12 | H5: 960000 | I5: 491200 | J5: 100 | K5: 42032 | M5: =H5 -> 960000 | N5: =M5*0.08 -> 76800 | O5: =M5-N5 -> 883200 | P5: =IF(O5<=300000,0,IF(O5>=20000000,(O5*0.21),(O5*0.2)+200000)) -> 376640 | Q5: =+M5-P5-N5 -> 506560 | R5: =IF(P5=0,(M5*0.01),IF(Q5<=0,0.01*M5,IF(AND(Q5>0,Q5<=300000),Q5*7%,IF(AND(Q5>=300000,Q5<600000),21000+(Q5-300000)*11%,IF(AND(Q5>=600000,Q5<1100000),54000+(Q5-600000)*15%,IF(AND(Q5>=1100000,Q5<1600000),129000+(Q5-1100000)*19%,IF(AND(Q5>=1600000,Q5<3200000),224000+(Q5-1600000)*21%,560000+(Q5-3200000)*24%))))))) -> 43721.6 | S5: =R5/12 -> 3643.4667 | T5: =G5 -> 12 | U5: =+S5*T5 -> 43721.6
A6: 3 | B6: N-4078857 | C6: Adesola | D6: Adeyinka | F6: Account officer | G6: 12 | H6: 660000 | I6: 275200 | J6: 100 | K6: 19264 | M6: =H6 -> 660000 | N6: =M6*0.08 -> 52800 | O6: =M6-N6 -> 607200 | P6: =IF(O6<=300000,0,IF(O6>=20000000,(O6*0.21),(O6*0.2)+200000)) -> 321440 | Q6: =+M6-P6-N6 -> 285760 | R6: =IF(P6=0,(M6*0.01),IF(Q6<=0,0.01*M6,IF(AND(Q6>0,Q6<=300000),Q6*7%,IF(AND(Q6>=300000,Q6<600000),21000+(Q6-300000)*11%,IF(AND(Q6>=600000,Q6<1100000),54000+(Q6-600000)*15%,IF(AND(Q6>=1100000,Q6<1600000),129000+(Q6-1100000)*19%,IF(AND(Q6>=1600000,Q6<3200000),224000+(Q6-1600000)*21%,560000+(Q6-3200000)*24%))))))) -> 20003.2 | S6: =R6/12 -> 1666.9333 | T6: =G6 -> 12 | U6: =+S6*T6 -> 20003.2
A7: 4 | B7: N-4081285 | C7: Egbuchulam | D7: Francis | F7: Electronics Aftersales Manager | G7: 12 | H7: 600000 | I7: 232000 | J7: 100 | K7: 16240 | M7: =H7 -> 600000 | N7: =M7*0.08 -> 48000 | O7: =M7-N7 -> 552000 | P7: =IF(O7<=300000,0,IF(O7>=20000000,(O7*0.21),(O7*0.2)+200000)) -> 310400 | Q7: =+M7-P7-N7 -> 241600 | R7: =IF(P7=0,(M7*0.01),IF(Q7<=0,0.01*M7,IF(AND(Q7>0,Q7<=300000),Q7*7%,IF(AND(Q7>=300000,Q7<600000),21000+(Q7-300000)*11%,IF(AND(Q7>=600000,Q7<1100000),54000+(Q7-600000)*15%,IF(AND(Q7>=1100000,Q7<1600000),129000+(Q7-1100000)*19%,IF(AND(Q7>=1600000,Q7<3200000),224000+(Q7-1600000)*21%,560000+(Q7-3200000)*24%))))))) -> 16912 | S7: =R7/12 -> 1409.3333 | T7: =G7 -> 12 | U7: =+S7*T7 -> 16912
A8: 5 | B8: N-4129622 | C8: Timothy | D8: O | E8: Ikponmwen | F8: Manager | G8: 12 | H8: 600000 | I8: 232000 | J8: 100 | K8: 16240 | M8: =H8 -> 600000 | N8: =M8*0.08 -> 48000 | O8: =M8-N8 -> 552000 | P8: =IF(O8<=300000,0,IF(O8>=20000000,(O8*0.21),(O8*0.2)+200000)) -> 310400 | Q8: =+M8-P8-N8 -> 241600 | R8: =IF(P8=0,(M8*0.01),IF(Q8<=0,0.01*M8,IF(AND(Q8>0,Q8<=300000),Q8*7%,IF(AND(Q8>=300000,Q8<600000),21000+(Q8-300000)*11%,IF(AND(Q8>=600000,Q8<1100000),54000+(Q8-600000)*15%,IF(AND(Q8>=1100000,Q8<1600000),129000+(Q8-1100000)*19%,IF(AND(Q8>=1600000,Q8<3200000),224000+(Q8-1600000)*21%,560000+(Q8-3200000)*24%))))))) -> 16912 | S8: =R8/12 -> 1409.3333 | T8: =G8 -> 12 | U8: =+S8*T8 -> 16912
A9: 6 | B9: N-4345599 | C9: Kolawole | D9: Opeyemi | F9: Material Officer | G9: 12 | H9: 420000 | I9: 102400 | J9: 100 | K9: 7168 | M9: =H9 -> 420000 | N9: =M9*0.08 -> 33600 | O9: =M9-N9 -> 386400 | P9: =IF(O9<=300000,0,IF(O9>=20000000,(O9*0.21),(O9*0.2)+200000)) -> 277280 | Q9: =+M9-P9-N9 -> 109120 | R9: =IF(P9=0,(M9*0.01),IF(Q9<=0,0.01*M9,IF(AND(Q9>0,Q9<=300000),Q9*7%,IF(AND(Q9>=300000,Q9<600000),21000+(Q9-300000)*11%,IF(AND(Q9>=600000,Q9<1100000),54000+(Q9-600000)*15%,IF(AND(Q9>=1100000,Q9<1600000),129000+(Q9-1100000)*19%,IF(AND(Q9>=1600000,Q9<3200000),224000+(Q9-1600000)*21%,560000+(Q9-3200000)*24%))))))) -> 7638.4 | S9: =R9/12 -> 636.53333 | T9: =G9 -> 12 | U9: =+S9*T9 -> 7638.4
A10: 7 | B10: N-4363325 | C10: Ginikanwa | D10: Darlington | E10: Uzoma | F10: Maintenance | G10: 12 | H10: 420000 | I10: 102400 | J10: 100 | K10: 7168 | M10: =H10 -> 420000 | N10: =M10*0.08 -> 33600 | O10: =M10-N10 -> 386400 | P10: =IF(O10<=300000,0,IF(O10>=20000000,(O10*0.21),(O10*0.2)+200000)) -> 277280 | Q10: =+M10-P10-N10 -> 109120 | R10: =IF(P10=0,(M10*0.01),IF(Q10<=0,0.01*M10,IF(AND(Q10>0,Q10<=300000),Q10*7%,IF(AND(Q10>=300000,Q10<600000),21000+(Q10-300000)*11%,IF(AND(Q10>=600000,Q10<1100000),54000+(Q10-600000)*15%,IF(AND(Q10>=1100000,Q10<1600000),129000+(Q10-1100000)*19%,IF(AND(Q10>=1600000,Q10<3200000),224000+(Q10-1600000)*21%,560000+(Q10-3200000)*24%))))))) -> 7638.4 | S10: =R10/12 -> 636.53333 | T10: =G10 -> 12 | U10: =+S10*T10 -> 7638.4
A11: 8 | B11: N-4363640 | C11: Kuponu | D11: Sesi | E11: Egbemimo | F11: Manager | G11: 12 | H11: 540000 | I11: 188800 | J11: 100 | K11: 13216 | M11: =H11 -> 540000 | N11: =M11*0.08 -> 43200 | O11: =M11-N11 -> 496800 | P11: =IF(O11<=300000,0,IF(O11>=20000000,(O11*0.21),(O11*0.2)+200000)) -> 299360 | Q11: =+M11-P11-N11 -> 197440 | R11: =IF(P11=0,(M11*0.01),IF(Q11<=0,0.01*M11,IF(AND(Q11>0,Q11<=300000),Q11*7%,IF(AND(Q11>=300000,Q11<600000),21000+(Q11-300000)*11%,IF(AND(Q11>=600000,Q11<1100000),54000+(Q11-600000)*15%,IF(AND(Q11>=1100000,Q11<1600000),129000+(Q11-1100000)*19%,IF(AND(Q11>=1600000,Q11<3200000),224000+(Q11-1600000)*21%,560000+(Q11-3200000)*24%))))))) -> 13820.8 | S11: =R11/12 -> 1151.7333 | T11: =G11 -> 12 | U11: =+S11*T11 -> 13820.8
A12: 9 | B12: N-4364503 | C12: Ayira | D12: Peace | F12: Cashier | G12: 12 | H12: 480000 | I12: 145600 | J12: 100 | K12: 10192 | M12: =H12 -> 480000 | N12: =M12*0.08 -> 38400 | O12: =M12-N12 -> 441600 | P12: =IF(O12<=300000,0,IF(O12>=20000000,(O12*0.21),(O12*0.2)+200000)) -> 288320 | Q12: =+M12-P12-N12 -> 153280 | R12: =IF(P12=0,(M12*0.01),IF(Q12<=0,0.01*M12,IF(AND(Q12>0,Q12<=300000),Q12*7%,IF(AND(Q12>=300000,Q12<600000),21000+(Q12-300000)*11%,IF(AND(Q12>=600000,Q12<1100000),54000+(Q12-600000)*15%,IF(AND(Q12>=1100000,Q12<1600000),129000+(Q12-1100000)*19%,IF(AND(Q12>=1600000,Q12<3200000),224000+(Q12-1600000)*21%,560000+(Q12-3200000)*24%))))))) -> 10729.6 | S12: =R12/12 -> 894.13333 | T12: =G12 -> 12 | U12: =+S12*T12 -> 10729.6
A13: 10 | B13: N-4364986 | C13: Kusagba | D13: Oluwakayode | F13: Stock Audior | G13: 12 | H13: 660000 | I13: 275200 | J13: 100 | K13: 19264 | M13: =H13 -> 660000 | N13: =M13*0.08 -> 52800 | O13: =M13-N13 -> 607200 | P13: =IF(O13<=300000,0,IF(O13>=20000000,(O13*0.21),(O13*0.2)+200000)) -> 321440 | Q13: =+M13-P13-N13 -> 285760 | R13: =IF(P13=0,(M13*0.01),IF(Q13<=0,0.01*M13,IF(AND(Q13>0,Q13<=300000),Q13*7%,IF(AND(Q13>=300000,Q13<600000),21000+(Q13-300000)*11%,IF(AND(Q13>=600000,Q13<1100000),54000+(Q13-600000)*15%,IF(AND(Q13>=1100000,Q13<1600000),129000+(Q13-1100000)*19%,IF(AND(Q13>=1600000,Q13<3200000),224000+(Q13-1600000)*21%,560000+(Q13-3200000)*24%))))))) -> 20003.2 | S13: =R13/12 -> 1666.9333 | T13: =G13 -> 12 | U13: =+S13*T13 -> 20003.2
A14: 11 | B14: N-4369098 | C14: Okoro | D14: Lilian | F14: Cashier | G14: 12 | H14: 480000 | I14: 145600 | J14: 100 | K14: 10192 | M14: =H14 -> 480000 | N14: =M14*0.08 -> 38400 | O14: =M14-N14 -> 441600 | P14: =IF(O14<=300000,0,IF(O14>=20000000,(O14*0.21),(O14*0.2)+200000)) -> 288320 | Q14: =+M14-P14-N14 -> 153280 | R14: =IF(P14=0,(M14*0.01),IF(Q14<=0,0.01*M14,IF(AND(Q14>0,Q14<=300000),Q14*7%,IF(AND(Q14>=300000,Q14<600000),21000+(Q14-300000)*11%,IF(AND(Q14>=600000,Q14<1100000),54000+(Q14-600000)*15%,IF(AND(Q14>=1100000,Q14<1600000),129000+(Q14-1100000)*19%,IF(AND(Q14>=1600000,Q14<3200000),224000+(Q14-1600000)*21%,560000+(Q14-3200000)*24%))))))) -> 10729.6 | S14: =R14/12 -> 894.13333 | T14: =G14 -> 12 | U14: =+S14*T14 -> 10729.6
A15: 12 | B15: N-4370821 | C15: Happiness | D15: Peace | F15: Store Supervisor | G15: 12 | H15: 540000 | I15: 188800 | J15: 100 | K15: 13216 | M15: =H15 -> 540000 | N15: =M15*0.08 -> 43200 | O15: =M15-N15 -> 496800 | P15: =IF(O15<=300000,0,IF(O15>=20000000,(O15*0.21),(O15*0.2)+200000)) -> 299360 | Q15: =+M15-P15-N15 -> 197440 | R15: =IF(P15=0,(M15*0.01),IF(Q15<=0,0.01*M15,IF(AND(Q15>0,Q15<=300000),Q15*7%,IF(AND(Q15>=300000,Q15<600000),21000+(Q15-300000)*11%,IF(AND(Q15>=600000,Q15<1100000),54000+(Q15-600000)*15%,IF(AND(Q15>=1100000,Q15<1600000),129000+(Q15-1100000)*19%,IF(AND(Q15>=1600000,Q15<3200000),224000+(Q15-1600000)*21%,560000+(Q15-3200000)*24%))))))) -> 13820.8 | S15: =R15/12 -> 1151.7333 | T15: =G15 -> 12 | U15: =+S15*T15 -> 13820.8
A16: 13 | B16: N-4374519 | C16: Ezioha | D16: Joel | E16: Ifeanyi | F16: Store Supervisor | G16: 12 | H16: 540000 | I16: 188800 | J16: 100 | K16: 13216 | M16: =H16 -> 540000 | N16: =M16*0.08 -> 43200 | O16: =M16-N16 -> 496800 | P16: =IF(O16<=300000,0,IF(O16>=20000000,(O16*0.21),(O16*0.2)+200000)) -> 299360 | Q16: =+M16-P16-N16 -> 197440 | R16: =IF(P16=0,(M16*0.01),IF(Q16<=0,0.01*M16,IF(AND(Q16>0,Q16<=300000),Q16*7%,IF(AND(Q16>=300000,Q16<600000),21000+(Q16-300000)*11%,IF(AND(Q16>=600000,Q16<1100000),54000+(Q16-600000)*15%,IF(AND(Q16>=1100000,Q16<1600000),129000+(Q16-1100000)*19%,IF(AND(Q16>=1600000,Q16<3200000),224000+(Q16-1600000)*21%,560000+(Q16-3200000)*24%))))))) -> 13820.8 | S16: =R16/12 -> 1151.7333 | T16: =G16 -> 12 | U16: =+S16*T16 -> 13820.8
A17: 14 | B17: N-4375382 | C17: Omolewa | D17: Mobolaji | F17: Cashier | G17: 12 | H17: 480000 | I17: 145600 | J17: 100 | K17: 10192 | M17: =H17 -> 480000 | N17: =M17*0.08 -> 38400 | O17: =M17-N17 -> 441600 | P17: =IF(O17<=300000,0,IF(O17>=20000000,(O17*0.21),(O17*0.2)+200000)) -> 288320 | Q17: =+M17-P17-N17 -> 153280 | R17: =IF(P17=0,(M17*0.01),IF(Q17<=0,0.01*M17,IF(AND(Q17>0,Q17<=300000),Q17*7%,IF(AND(Q17>=300000,Q17<600000),21000+(Q17-300000)*11%,IF(AND(Q17>=600000,Q17<1100000),54000+(Q17-600000)*15%,IF(AND(Q17>=1100000,Q17<1600000),129000+(Q17-1100000)*19%,IF(AND(Q17>=1600000,Q17<3200000),224000+(Q17-1600000)*21%,560000+(Q17-3200000)*24%))))))) -> 10729.6 | S17: =R17/12 -> 894.13333 | T17: =G17 -> 12 | U17: =+S17*T17 -> 10729.6
A18: 15 | B18: N-4377083 | C18: Oguh | D18: Chrysantus | E18: Ogadimma | F18: Maintainance | G18: 12 | H18: 420000 | I18: 102400 | J18: 100 | K18: 7168 | M18: =H18 -> 420000 | N18: =M18*0.08 -> 33600 | O18: =M18-N18 -> 386400 | P18: =IF(O18<=300000,0,IF(O18>=20000000,(O18*0.21),(O18*0.2)+200000)) -> 277280 | Q18: =+M18-P18-N18 -> 109120 | R18: =IF(P18=0,(M18*0.01),IF(Q18<=0,0.01*M18,IF(AND(Q18>0,Q18<=300000),Q18*7%,IF(AND(Q18>=300000,Q18<600000),21000+(Q18-300000)*11%,IF(AND(Q18>=600000,Q18<1100000),54000+(Q18-600000)*15%,IF(AND(Q18>=1100000,Q18<1600000),129000+(Q18-1100000)*19%,IF(AND(Q18>=1600000,Q18<3200000),224000+(Q18-1600000)*21%,560000+(Q18-3200000)*24%))))))) -> 7638.4 | S18: =R18/12 -> 636.53333 | T18: =G18 -> 12 | U18: =+S18*T18 -> 7638.4
A19: 16 | B19: N-4382660 | C19: Adetunji | D19: John | E19: Oluwatosin | F19: Manager | G19: 12 | H19: 540000 | I19: 188800 | J19: 100 | K19: 13216 | M19: =H19 -> 540000 | N19: =M19*0.08 -> 43200 | O19: =M19-N19 -> 496800 | P19: =IF(O19<=300000,0,IF(O19>=20000000,(O19*0.21),(O19*0.2)+200000)) -> 299360 | Q19: =+M19-P19-N19 -> 197440 | R19: =IF(P19=0,(M19*0.01),IF(Q19<=0,0.01*M19,IF(AND(Q19>0,Q19<=300000),Q19*7%,IF(AND(Q19>=300000,Q19<600000),21000+(Q19-300000)*11%,IF(AND(Q19>=600000,Q19<1100000),54000+(Q19-600000)*15%,IF(AND(Q19>=1100000,Q19<1600000),129000+(Q19-1100000)*19%,IF(AND(Q19>=1600000,Q19<3200000),224000+(Q19-1600000)*21%,560000+(Q19-3200000)*24%))))))) -> 13820.8 | S19: =R19/12 -> 1151.7333 | T19: =G19 -> 12 | U19: =+S19*T19 -> 13820.8
A20: 17 | B20: N-4398715 | C20: Otache | D20: Ruth | E20: Ene | F20: Cashier | G20: 12 | H20: 480000 | I20: 145600 | J20: 100 | K20: 10192 | M20: =H20 -> 480000 | N20: =M20*0.08 -> 38400 | O20: =M20-N20 -> 441600 | P20: =IF(O20<=300000,0,IF(O20>=20000000,(O20*0.21),(O20*0.2)+200000)) -> 288320 | Q20: =+M20-P20-N20 -> 153280 | R20: =IF(P20=0,(M20*0.01),IF(Q20<=0,0.01*M20,IF(AND(Q20>0,Q20<=300000),Q20*7%,IF(AND(Q20>=300000,Q20<600000),21000+(Q20-300000)*11%,IF(AND(Q20>=600000,Q20<1100000),54000+(Q20-600000)*15%,IF(AND(Q20>=1100000,Q20<1600000),129000+(Q20-1100000)*19%,IF(AND(Q20>=1600000,Q20<3200000),224000+(Q20-1600000)*21%,560000+(Q20-3200000)*24%))))))) -> 10729.6 | S20: =R20/12 -> 894.13333 | T20: =G20 -> 12 | U20: =+S20*T20 -> 10729.6
A21: 18 | B21: N-4398923 | C21: Roland | D21: Ebramieta | F21: Maintainance | G21: 12 | H21: 420000 | I21: 102400 | J21: 100 | K21: 7168 | M21: =H21 -> 420000 | N21: =M21*0.08 -> 33600 | O21: =M21-N21 -> 386400 | P21: =IF(O21<=300000,0,IF(O21>=20000000,(O21*0.21),(O21*0.2)+200000)) -> 277280 | Q21: =+M21-P21-N21 -> 109120 | R21: =IF(P21=0,(M21*0.01),IF(Q21<=0,0.01*M21,IF(AND(Q21>0,Q21<=300000),Q21*7%,IF(AND(Q21>=300000,Q21<600000),21000+(Q21-300000)*11%,IF(AND(Q21>=600000,Q21<1100000),54000+(Q21-600000)*15%,IF(AND(Q21>=1100000,Q21<1600000),129000+(Q21-1100000)*19%,IF(AND(Q21>=1600000,Q21<3200000),224000+(Q21-1600000)*21%,560000+(Q21-3200000)*24%))))))) -> 7638.4 | S21: =R21/12 -> 636.53333 | T21: =G21 -> 12 | U21: =+S21*T21 -> 7638.4
A22: 19 | B22: N-4399054 | C22: Adesina | D22: Olawole | E22: Daniel | F22: Maintenance | G22: 12 | H22: 420000 | I22: 102400 | J22: 100 | K22: 7168 | M22: =H22 -> 420000 | N22: =M22*0.08 -> 33600 | O22: =M22-N22 -> 386400 | P22: =IF(O22<=300000,0,IF(O22>=20000000,(O22*0.21),(O22*0.2)+200000)) -> 277280 | Q22: =+M22-P22-N22 -> 109120 | R22: =IF(P22=0,(M22*0.01),IF(Q22<=0,0.01*M22,IF(AND(Q22>0,Q22<=300000),Q22*7%,IF(AND(Q22>=300000,Q22<600000),21000+(Q22-300000)*11%,IF(AND(Q22>=600000,Q22<1100000),54000+(Q22-600000)*15%,IF(AND(Q22>=1100000,Q22<1600000),129000+(Q22-1100000)*19%,IF(AND(Q22>=1600000,Q22<3200000),224000+(Q22-1600000)*21%,560000+(Q22-3200000)*24%))))))) -> 7638.4 | S22: =R22/12 -> 636.53333 | T22: =G22 -> 12 | U22: =+S22*T22 -> 7638.4
A23: 20 | B23: N-4399142 | C23: Onyenoro | D23: Obinna | F23: Trainee Manager | G23: 12 | H23: 480000 | I23: 145600 | J23: 100 | K23: 10192 | M23: =H23 -> 480000 | N23: =M23*0.08 -> 38400 | O23: =M23-N23 -> 441600 | P23: =IF(O23<=300000,0,IF(O23>=20000000,(O23*0.21),(O23*0.2)+200000)) -> 288320 | Q23: =+M23-P23-N23 -> 153280 | R23: =IF(P23=0,(M23*0.01),IF(Q23<=0,0.01*M23,IF(AND(Q23>0,Q23<=300000),Q23*7%,IF(AND(Q23>=300000,Q23<600000),21000+(Q23-300000)*11%,IF(AND(Q23>=600000,Q23<1100000),54000+(Q23-600000)*15%,IF(AND(Q23>=1100000,Q23<1600000),129000+(Q23-1100000)*19%,IF(AND(Q23>=1600000,Q23<3200000),224000+(Q23-1600000)*21%,560000+(Q23-3200000)*24%))))))) -> 10729.6 | S23: =R23/12 -> 894.13333 | T23: =G23 -> 12 | U23: =+S23*T23 -> 10729.6
A24: 21 | B24: N-4405398 | C24: Olusola | D24: Odunayo | F24: Assistant Sales Manager | G24: 12 | H24: 540000 | I24: 188800 | J24: 100 | K24: 13216 | M24: =H24 -> 540000 | N24: =M24*0.08 -> 43200 | O24: =M24-N24 -> 496800 | P24: =IF(O24<=300000,0,IF(O24>=20000000,(O24*0.21),(O24*0.2)+200000)) -> 299360 | Q24: =+M24-P24-N24 -> 197440 | R24: =IF(P24=0,(M24*0.01),IF(Q24<=0,0.01*M24,IF(AND(Q24>0,Q24<=300000),Q24*7%,IF(AND(Q24>=300000,Q24<600000),21000+(Q24-300000)*11%,IF(AND(Q24>=600000,Q24<1100000),54000+(Q24-600000)*15%,IF(AND(Q24>=1100000,Q24<1600000),129000+(Q24-1100000)*19%,IF(AND(Q24>=1600000,Q24<3200000),224000+(Q24-1600000)*21%,560000+(Q24-3200000)*24%))))))) -> 13820.8 | S24: =R24/12 -> 1151.7333 | T24: =G24 -> 12 | U24: =+S24*T24 -> 13820.8
A25: 22 | B25: N-4409529 | C25: Olorunsina | D25: Kemi | F25: Cashier | G25: 12 | H25: 480000 | I25: 145600 | J25: 100 | K25: 10192 | M25: =H25 -> 480000 | N25: =M25*0.08 -> 38400 | O25: =M25-N25 -> 441600 | P25: =IF(O25<=300000,0,IF(O25>=20000000,(O25*0.21),(O25*0.2)+200000)) -> 288320 | Q25: =+M25-P25-N25 -> 153280 | R25: =IF(P25=0,(M25*0.01),IF(Q25<=0,0.01*M25,IF(AND(Q25>0,Q25<=300000),Q25*7%,IF(AND(Q25>=300000,Q25<600000),21000+(Q25-300000)*11%,IF(AND(Q25>=600000,Q25<1100000),54000+(Q25-600000)*15%,IF(AND(Q25>=1100000,Q25<1600000),129000+(Q25-1100000)*19%,IF(AND(Q25>=1600000,Q25<3200000),224000+(Q25-1600000)*21%,560000+(Q25-3200000)*24%))))))) -> 10729.6 | S25: =R25/12 -> 894.13333 | T25: =G25 -> 12 | U25: =+S25*T25 -> 10729.6
A26: 23 | B26: N-4410880 | C26: Moshood | D26: Rasheed | F26: Maintainance | G26: 12 | H26: 420000 | I26: 102400 | J26: 100 | K26: 7168 | M26: =H26 -> 420000 | N26: =M26*0.08 -> 33600 | O26: =M26-N26 -> 386400 | P26: =IF(O26<=300000,0,IF(O26>=20000000,(O26*0.21),(O26*0.2)+200000)) -> 277280 | Q26: =+M26-P26-N26 -> 109120 | R26: =IF(P26=0,(M26*0.01),IF(Q26<=0,0.01*M26,IF(AND(Q26>0,Q26<=300000),Q26*7%,IF(AND(Q26>=300000,Q26<600000),21000+(Q26-300000)*11%,IF(AND(Q26>=600000,Q26<1100000),54000+(Q26-600000)*15%,IF(AND(Q26>=1100000,Q26<1600000),129000+(Q26-1100000)*19%,IF(AND(Q26>=1600000,Q26<3200000),224000+(Q26-1600000)*21%,560000+(Q26-3200000)*24%))))))) -> 7638.4 | S26: =R26/12 -> 636.53333 | T26: =G26 -> 12 | U26: =+S26*T26 -> 7638.4
A27: 24 | B27: N-4411214 | C27: Babalola | D27: omolara | E27: A | F27: Cashier | G27: 12 | H27: 480000 | I27: 145600 | J27: 100 | K27: 10192 | M27: =H27 -> 480000 | N27: =M27*0.08 -> 38400 | O27: =M27-N27 -> 441600 | P27: =IF(O27<=300000,0,IF(O27>=20000000,(O27*0.21),(O27*0.2)+200000)) -> 288320 | Q27: =+M27-P27-N27 -> 153280 | R27: =IF(P27=0,(M27*0.01),IF(Q27<=0,0.01*M27,IF(AND(Q27>0,Q27<=300000),Q27*7%,IF(AND(Q27>=300000,Q27<600000),21000+(Q27-300000)*11%,IF(AND(Q27>=600000,Q27<1100000),54000+(Q27-600000)*15%,IF(AND(Q27>=1100000,Q27<1600000),129000+(Q27-1100000)*19%,IF(AND(Q27>=1600000,Q27<3200000),224000+(Q27-1600000)*21%,560000+(Q27-3200000)*24%))))))) -> 10729.6 | S27: =R27/12 -> 894.13333 | T27: =G27 -> 12 | U27: =+S27*T27 -> 10729.6
A28: 25 | B28: N-4421971 | C28: Ehiagwina | D28: E. | E28: Peter | F28: Manager | G28: 12 | H28: 660000 | I28: 275200 | J28: 100 | K28: 19264 | M28: =H28 -> 660000 | N28: =M28*0.08 -> 52800 | O28: =M28-N28 -> 607200 | P28: =IF(O28<=300000,0,IF(O28>=20000000,(O28*0.21),(O28*0.2)+200000)) -> 321440 | Q28: =+M28-P28-N28 -> 285760 | R28: =IF(P28=0,(M28*0.01),IF(Q28<=0,0.01*M28,IF(AND(Q28>0,Q28<=300000),Q28*7%,IF(AND(Q28>=300000,Q28<600000),21000+(Q28-300000)*11%,IF(AND(Q28>=600000,Q28<1100000),54000+(Q28-600000)*15%,IF(AND(Q28>=1100000,Q28<1600000),129000+(Q28-1100000)*19%,IF(AND(Q28>=1600000,Q28<3200000),224000+(Q28-1600000)*21%,560000+(Q28-3200000)*24%))))))) -> 20003.2 | S28: =R28/12 -> 1666.9333 | T28: =G28 -> 12 | U28: =+S28*T28 -> 20003.2
A29: 26 | B29: N-4423754 | C29: Oduyebo | D29: Samuel | F29: Manager | G29: 12 | H29: 540000 | I29: 188800 | J29: 100 | K29: 13216 | M29: =H29 -> 540000 | N29: =M29*0.08 -> 43200 | O29: =M29-N29 -> 496800 | P29: =IF(O29<=300000,0,IF(O29>=20000000,(O29*0.21),(O29*0.2)+200000)) -> 299360 | Q29: =+M29-P29-N29 -> 197440 | R29: =IF(P29=0,(M29*0.01),IF(Q29<=0,0.01*M29,IF(AND(Q29>0,Q29<=300000),Q29*7%,IF(AND(Q29>=300000,Q29<600000),21000+(Q29-300000)*11%,IF(AND(Q29>=600000,Q29<1100000),54000+(Q29-600000)*15%,IF(AND(Q29>=1100000,Q29<1600000),129000+(Q29-1100000)*19%,IF(AND(Q29>=1600000,Q29<3200000),224000+(Q29-1600000)*21%,560000+(Q29-3200000)*24%))))))) -> 13820.8 | S29: =R29/12 -> 1151.7333 | T29: =G29 -> 12 | U29: =+S29*T29 -> 13820.8
A30: 27 | B30: N-4443819 | C30: Ndukuba | D30: Uzoamaka | F30: Logistics Assistant 1 | G30: 12 | H30: 540000 | I30: 188800 | J30: 100 | K30: 13216 | M30: =H30 -> 540000 | N30: =M30*0.08 -> 43200 | O30: =M30-N30 -> 496800 | P30: =IF(O30<=300000,0,IF(O30>=20000000,(O30*0.21),(O30*0.2)+200000)) -> 299360 | Q30: =+M30-P30-N30 -> 197440 | R30: =IF(P30=0,(M30*0.01),IF(Q30<=0,0.01*M30,IF(AND(Q30>0,Q30<=300000),Q30*7%,IF(AND(Q30>=300000,Q30<600000),21000+(Q30-300000)*11%,IF(AND(Q30>=600000,Q30<1100000),54000+(Q30-600000)*15%,IF(AND(Q30>=1100000,Q30<1600000),129000+(Q30-1100000)*19%,IF(AND(Q30>=1600000,Q30<3200000),224000+(Q30-1600000)*21%,560000+(Q30-3200000)*24%))))))) -> 13820.8 | S30: =R30/12 -> 1151.7333 | T30: =G30 -> 12 | U30: =+S30*T30 -> 13820.8
A31: 28 | B31: N-4443831 | C31: Ajayi | D31: Olasunkanmi | E31: Tunde | F31: Purchase Assistant | G31: 12 | H31: 960000 | I31: 491200 | J31: 100 | K31: 42032 | M31: =H31 -> 960000 | N31: =M31*0.08 -> 76800 | O31: =M31-N31 -> 883200 | P31: =IF(O31<=300000,0,IF(O31>=20000000,(O31*0.21),(O31*0.2)+200000)) -> 376640 | Q31: =+M31-P31-N31 -> 506560 | R31: =IF(P31=0,(M31*0.01),IF(Q31<=0,0.01*M31,IF(AND(Q31>0,Q31<=300000),Q31*7%,IF(AND(Q31>=300000,Q31<600000),21000+(Q31-300000)*11%,IF(AND(Q31>=600000,Q31<1100000),54000+(Q31-600000)*15%,IF(AND(Q31>=1100000,Q31<1600000),129000+(Q31-1100000)*19%,IF(AND(Q31>=1600000,Q31<3200000),224000+(Q31-1600000)*21%,560000+(Q31-3200000)*24%))))))) -> 43721.6 | S31: =R31/12 -> 3643.4667 | T31: =G31 -> 12 | U31: =+S31*T31 -> 43721.6
A32: 29 | B32: N-4443874 | C32: Jolayemi | D32: Solomon | E32: Oluwaseun | F32: Instock & Transfer | G32: 12 | H32: 660000 | I32: 275200 | J32: 100 | K32: 19264 | M32: =H32 -> 660000 | N32: =M32*0.08 -> 52800 | O32: =M32-N32 -> 607200 | P32: =IF(O32<=300000,0,IF(O32>=20000000,(O32*0.21),(O32*0.2)+200000)) -> 321440 | Q32: =+M32-P32-N32 -> 285760 | R32: =IF(P32=0,(M32*0.01),IF(Q32<=0,0.01*M32,IF(AND(Q32>0,Q32<=300000),Q32*7%,IF(AND(Q32>=300000,Q32<600000),21000+(Q32-300000)*11%,IF(AND(Q32>=600000,Q32<1100000),54000+(Q32-600000)*15%,IF(AND(Q32>=1100000,Q32<1600000),129000+(Q32-1100000)*19%,IF(AND(Q32>=1600000,Q32<3200000),224000+(Q32-1600000)*21%,560000+(Q32-3200000)*24%))))))) -> 20003.2 | S32: =R32/12 -> 1666.9333 | T32: =G32 -> 12 | U32: =+S32*T32 -> 20003.2
